## 2025-09-21 00:51:31,330
__main__ - INFO
Environment variables check:

---

## 2025-09-21 00:51:31,331
__main__ - INFO
METACULUS_TOKEN: SET

---

## 2025-09-21 00:51:31,331
__main__ - INFO
OPENROUTER_API_KEY: SET

---

## 2025-09-21 00:51:31,331
__main__ - INFO
OPENAI_API_KEY: SET

---

## 2025-09-21 00:51:31,331
__main__ - INFO
LITELLM_OPENROUTER_API_KEY: NOT SET

---

## 2025-09-21 00:51:31,331
__main__ - INFO
LITELLM_OPENAI_API_KEY: NOT SET

---

## 2025-09-21 00:51:31,331
__main__ - INFO
PERPLEXITY_API_KEY: SET

---

## 2025-09-21 00:51:31,333
__main__ - INFO
EXA_API_KEY: SET

---

## 2025-09-21 00:51:31,333
__main__ - INFO
ANTHROPIC_API_KEY: SET

---

## 2025-09-21 00:51:31,333
__main__ - INFO
ASKNEWS_CLIENT_ID: SET

---

## 2025-09-21 00:51:31,333
__main__ - INFO
ASKNEWS_SECRET: SET

---

## 2025-09-21 00:51:31,338
__main__ - INFO
Starting test questions mode

---

## 2025-09-21 00:51:47,873
__main__ - INFO
Found Research for URL dummy://test.com:
Title: Research Topic: Latest Anti-Aging Medical Breakthroughs

Summary: This research focuses on the latest breakthroughs in anti-aging medicine, relevant for predicting human longevity. Although no specific articles were found, advancements in this field are crucial for addressing the forecasting question: What will be the age of the oldest human by 2100? The current record for human longevity is 122 years. Ongoing developments in medical science could potentially extend this record, making this topic significant for future projections.

---

## 2025-09-21 00:52:23,091
__main__ - INFO
Forecasting completed successfully

---

## 2025-09-21 00:52:23,376
__main__ - ERROR
An unexpected error occurred: 1 errors occurred while forecasting: [ExceptionGroup('Error while processing question url: \'dummy://test.com\': All 1 research reports/predictions failed: Errors: ["ExceptionGroup: Error while running research and predictions: Errors: [\'RetryError: RetryError[<Future at 0x198aafe7d90 state=finished raised ValidationError>]\'] (1 sub-exception)"]', (ExceptionGroup("Error while running research and predictions: Errors: ['RetryError: RetryError[<Future at 0x198aafe7d90 state=finished raised ValidationError>]']", (RetryError(<Future at 0x198aafe7d90 state=finished raised ValidationError>),)),))]

---

## 2025-09-21 00:52:23,376
__main__ - ERROR
Error type: RuntimeError

---

## 2025-09-21 00:52:23,377
__main__ - ERROR
Full traceback: Traceback (most recent call last):
  File "C:\Users\jsgle\Desktop\AI\Guillotine Forecasting\guillotine-forecasting\main.py", line 1082, in main
    template_bot.log_report_summary(forecast_reports)
    ~~~~~~~~~~~~~~~~~~~~~~~~~~~~~~~^^^^^^^^^^^^^^^^^^
  File "C:\Users\jsgle\AppData\Local\pypoetry\Cache\virtualenvs\metac-bot-template-GWo1ehSY-py3.13\Lib\site-packages\forecasting_tools\forecast_bots\forecast_bot.py", line 762, in log_report_summary
    raise RuntimeError(
        f"{len(exceptions)} errors occurred while forecasting: {exceptions}"
    )
RuntimeError: 1 errors occurred while forecasting: [ExceptionGroup('Error while processing question url: \'dummy://test.com\': All 1 research reports/predictions failed: Errors: ["ExceptionGroup: Error while running research and predictions: Errors: [\'RetryError: RetryError[<Future at 0x198aafe7d90 state=finished raised ValidationError>]\'] (1 sub-exception)"]', (ExceptionGroup("Error while running research and predictions: Errors: ['RetryError: RetryError[<Future at 0x198aafe7d90 state=finished raised ValidationError>]']", (RetryError(<Future at 0x198aafe7d90 state=finished raised ValidationError>),)),))]


---

## 2025-09-21 00:52:23,378
__main__ - ERROR
Error during bot execution: 1 errors occurred while forecasting: [ExceptionGroup('Error while processing question url: \'dummy://test.com\': All 1 research reports/predictions failed: Errors: ["ExceptionGroup: Error while running research and predictions: Errors: [\'RetryError: RetryError[<Future at 0x198aafe7d90 state=finished raised ValidationError>]\'] (1 sub-exception)"]', (ExceptionGroup("Error while running research and predictions: Errors: ['RetryError: RetryError[<Future at 0x198aafe7d90 state=finished raised ValidationError>]']", (RetryError(<Future at 0x198aafe7d90 state=finished raised ValidationError>),)),))]

---

## 2025-09-21 00:52:23,378
__main__ - ERROR
Error type: RuntimeError

---

## 2025-09-21 00:52:23,379
__main__ - ERROR
Full traceback: Traceback (most recent call last):
  File "C:\Users\jsgle\Desktop\AI\Guillotine Forecasting\guillotine-forecasting\main.py", line 1100, in <module>
    main()
    ~~~~^^
  File "C:\Users\jsgle\Desktop\AI\Guillotine Forecasting\guillotine-forecasting\main.py", line 1082, in main
    template_bot.log_report_summary(forecast_reports)
    ~~~~~~~~~~~~~~~~~~~~~~~~~~~~~~~^^^^^^^^^^^^^^^^^^
  File "C:\Users\jsgle\AppData\Local\pypoetry\Cache\virtualenvs\metac-bot-template-GWo1ehSY-py3.13\Lib\site-packages\forecasting_tools\forecast_bots\forecast_bot.py", line 762, in log_report_summary
    raise RuntimeError(
        f"{len(exceptions)} errors occurred while forecasting: {exceptions}"
    )
RuntimeError: 1 errors occurred while forecasting: [ExceptionGroup('Error while processing question url: \'dummy://test.com\': All 1 research reports/predictions failed: Errors: ["ExceptionGroup: Error while running research and predictions: Errors: [\'RetryError: RetryError[<Future at 0x198aafe7d90 state=finished raised ValidationError>]\'] (1 sub-exception)"]', (ExceptionGroup("Error while running research and predictions: Errors: ['RetryError: RetryError[<Future at 0x198aafe7d90 state=finished raised ValidationError>]']", (RetryError(<Future at 0x198aafe7d90 state=finished raised ValidationError>),)),))]


---

