## 2025-09-19 14:20:40,010
__main__ - INFO
Environment variables check:

---

## 2025-09-19 14:20:40,011
__main__ - INFO
METACULUS_TOKEN: SET

---

## 2025-09-19 14:20:40,011
__main__ - INFO
OPENROUTER_API_KEY: SET

---

## 2025-09-19 14:20:40,011
__main__ - INFO
OPENAI_API_KEY: SET

---

## 2025-09-19 14:20:40,011
__main__ - INFO
LITELLM_OPENROUTER_API_KEY: NOT SET

---

## 2025-09-19 14:20:40,011
__main__ - INFO
LITELLM_OPENAI_API_KEY: NOT SET

---

## 2025-09-19 14:20:40,011
__main__ - INFO
PERPLEXITY_API_KEY: SET

---

## 2025-09-19 14:20:40,013
__main__ - INFO
EXA_API_KEY: SET

---

## 2025-09-19 14:20:40,013
__main__ - INFO
ANTHROPIC_API_KEY: SET

---

## 2025-09-19 14:20:40,014
__main__ - INFO
ASKNEWS_CLIENT_ID: SET

---

## 2025-09-19 14:20:40,014
__main__ - INFO
ASKNEWS_SECRET: SET

---

## 2025-09-19 14:20:40,022
__main__ - INFO
Starting test questions mode

---

## 2025-09-19 14:20:58,701
__main__ - INFO
Found Research for URL dummy://test.com:
Research on human longevity trends and lifespan predictions for 2100 is crucial for forecasting the age of the oldest human by that year. Despite no specific articles being found, these topics are highly relevant. The current record for human lifespan is 122 years, and advancements in medicine could potentially extend this. Understanding current trends and predictions in longevity research will aid in making informed forecasts about future human lifespans.

---

## 2025-09-19 14:21:03,960
__main__ - INFO
Forecasting completed successfully

---

## 2025-09-19 14:21:03,978
__main__ - ERROR
An unexpected error occurred: 1 errors occurred while forecasting: [ExceptionGroup('Error while processing question url: \'dummy://test.com\': All 1 research reports/predictions failed: Errors: ["ExceptionGroup: Error while running research and predictions: Errors: [\'RetryError: RetryError[<Future at 0x1e9f4a9d130 state=finished raised AttributeError>]\'] (1 sub-exception)"]', (ExceptionGroup("Error while running research and predictions: Errors: ['RetryError: RetryError[<Future at 0x1e9f4a9d130 state=finished raised AttributeError>]']", (RetryError(<Future at 0x1e9f4a9d130 state=finished raised AttributeError>),)),))]

---

## 2025-09-19 14:21:03,978
__main__ - ERROR
Error type: RuntimeError

---

## 2025-09-19 14:21:03,979
__main__ - ERROR
Full traceback: Traceback (most recent call last):
  File "C:\Users\jsgle\Desktop\AI\Guillotine Forecasting\guillotine-forecasting\main.py", line 1079, in main
    template_bot.log_report_summary(forecast_reports)
    ~~~~~~~~~~~~~~~~~~~~~~~~~~~~~~~^^^^^^^^^^^^^^^^^^
  File "C:\Users\jsgle\AppData\Roaming\pypoetry\venv\Lib\site-packages\forecasting_tools\forecast_bots\forecast_bot.py", line 806, in log_report_summary
    raise RuntimeError(
        f"{len(exceptions)} errors occurred while forecasting: {exceptions}"
    )
RuntimeError: 1 errors occurred while forecasting: [ExceptionGroup('Error while processing question url: \'dummy://test.com\': All 1 research reports/predictions failed: Errors: ["ExceptionGroup: Error while running research and predictions: Errors: [\'RetryError: RetryError[<Future at 0x1e9f4a9d130 state=finished raised AttributeError>]\'] (1 sub-exception)"]', (ExceptionGroup("Error while running research and predictions: Errors: ['RetryError: RetryError[<Future at 0x1e9f4a9d130 state=finished raised AttributeError>]']", (RetryError(<Future at 0x1e9f4a9d130 state=finished raised AttributeError>),)),))]


---

## 2025-09-19 14:21:03,979
__main__ - ERROR
Error during bot execution: 1 errors occurred while forecasting: [ExceptionGroup('Error while processing question url: \'dummy://test.com\': All 1 research reports/predictions failed: Errors: ["ExceptionGroup: Error while running research and predictions: Errors: [\'RetryError: RetryError[<Future at 0x1e9f4a9d130 state=finished raised AttributeError>]\'] (1 sub-exception)"]', (ExceptionGroup("Error while running research and predictions: Errors: ['RetryError: RetryError[<Future at 0x1e9f4a9d130 state=finished raised AttributeError>]']", (RetryError(<Future at 0x1e9f4a9d130 state=finished raised AttributeError>),)),))]

---

## 2025-09-19 14:21:03,980
__main__ - ERROR
Error type: RuntimeError

---

## 2025-09-19 14:21:03,981
__main__ - ERROR
Full traceback: Traceback (most recent call last):
  File "C:\Users\jsgle\Desktop\AI\Guillotine Forecasting\guillotine-forecasting\main.py", line 1097, in <module>
    main()
    ~~~~^^
  File "C:\Users\jsgle\Desktop\AI\Guillotine Forecasting\guillotine-forecasting\main.py", line 1079, in main
    template_bot.log_report_summary(forecast_reports)
    ~~~~~~~~~~~~~~~~~~~~~~~~~~~~~~~^^^^^^^^^^^^^^^^^^
  File "C:\Users\jsgle\AppData\Roaming\pypoetry\venv\Lib\site-packages\forecasting_tools\forecast_bots\forecast_bot.py", line 806, in log_report_summary
    raise RuntimeError(
        f"{len(exceptions)} errors occurred while forecasting: {exceptions}"
    )
RuntimeError: 1 errors occurred while forecasting: [ExceptionGroup('Error while processing question url: \'dummy://test.com\': All 1 research reports/predictions failed: Errors: ["ExceptionGroup: Error while running research and predictions: Errors: [\'RetryError: RetryError[<Future at 0x1e9f4a9d130 state=finished raised AttributeError>]\'] (1 sub-exception)"]', (ExceptionGroup("Error while running research and predictions: Errors: ['RetryError: RetryError[<Future at 0x1e9f4a9d130 state=finished raised AttributeError>]']", (RetryError(<Future at 0x1e9f4a9d130 state=finished raised AttributeError>),)),))]


---

