## 2025-09-23 00:03:46,581
__main__ - INFO
Environment variables check:

---

## 2025-09-23 00:03:46,582
__main__ - INFO
METACULUS_TOKEN: SET

---

## 2025-09-23 00:03:46,582
__main__ - INFO
OPENROUTER_API_KEY: SET

---

## 2025-09-23 00:03:46,582
__main__ - INFO
OPENAI_API_KEY: SET

---

## 2025-09-23 00:03:46,582
__main__ - INFO
LITELLM_OPENROUTER_API_KEY: NOT SET

---

## 2025-09-23 00:03:46,582
__main__ - INFO
LITELLM_OPENAI_API_KEY: NOT SET

---

## 2025-09-23 00:03:46,582
__main__ - INFO
PERPLEXITY_API_KEY: SET

---

## 2025-09-23 00:03:46,583
__main__ - INFO
EXA_API_KEY: SET

---

## 2025-09-23 00:03:46,583
__main__ - INFO
ANTHROPIC_API_KEY: SET

---

## 2025-09-23 00:03:46,583
__main__ - INFO
ASKNEWS_CLIENT_ID: SET

---

## 2025-09-23 00:03:46,583
__main__ - INFO
ASKNEWS_SECRET: SET

---

## 2025-09-23 00:03:46,585
__main__ - INFO
Starting test questions mode

---

## 2025-09-23 00:04:16,712
__main__ - INFO
Found Research for URL dummy://test.com:
Research on advancements in medicine, breakthroughs in life extension technology, and current trends in human longevity reveals no specific articles, but these topics are crucial for addressing the forecasting question: "What will be the age of the oldest human as of 2100?" The current longevity record is 122 years, and potential medical advancements could extend this. Understanding these research areas is essential for predicting future human lifespan trends.

---

## 2025-09-23 00:05:02,074
__main__ - INFO
Forecasting completed successfully

---

## 2025-09-23 00:05:02,203
__main__ - ERROR
An unexpected error occurred: 1 errors occurred while forecasting: [ExceptionGroup('Error while processing question url: \'dummy://test.com\': All 1 research reports/predictions failed: Errors: ["ExceptionGroup: Error while running research and predictions: Errors: [\'RetryError: RetryError[<Future at 0x1f4ba1aa0b0 state=finished raised ValidationError>]\'] (1 sub-exception)"]', (ExceptionGroup("Error while running research and predictions: Errors: ['RetryError: RetryError[<Future at 0x1f4ba1aa0b0 state=finished raised ValidationError>]']", (RetryError(<Future at 0x1f4ba1aa0b0 state=finished raised ValidationError>),)),))]

---

## 2025-09-23 00:05:02,203
__main__ - ERROR
Error type: RuntimeError

---

## 2025-09-23 00:05:02,203
__main__ - ERROR
Full traceback: Traceback (most recent call last):
  File "C:\Users\jsgle\Desktop\AI\Guillotine Forecasting\guillotine-forecasting\main.py", line 1099, in main
    template_bot.log_report_summary(forecast_reports)
    ~~~~~~~~~~~~~~~~~~~~~~~~~~~~~~~^^^^^^^^^^^^^^^^^^
  File "C:\Users\jsgle\AppData\Roaming\pypoetry\venv\Lib\site-packages\forecasting_tools\forecast_bots\forecast_bot.py", line 806, in log_report_summary
    raise RuntimeError(
        f"{len(exceptions)} errors occurred while forecasting: {exceptions}"
    )
RuntimeError: 1 errors occurred while forecasting: [ExceptionGroup('Error while processing question url: \'dummy://test.com\': All 1 research reports/predictions failed: Errors: ["ExceptionGroup: Error while running research and predictions: Errors: [\'RetryError: RetryError[<Future at 0x1f4ba1aa0b0 state=finished raised ValidationError>]\'] (1 sub-exception)"]', (ExceptionGroup("Error while running research and predictions: Errors: ['RetryError: RetryError[<Future at 0x1f4ba1aa0b0 state=finished raised ValidationError>]']", (RetryError(<Future at 0x1f4ba1aa0b0 state=finished raised ValidationError>),)),))]


---

## 2025-09-23 00:05:02,204
__main__ - ERROR
Error during bot execution: 1 errors occurred while forecasting: [ExceptionGroup('Error while processing question url: \'dummy://test.com\': All 1 research reports/predictions failed: Errors: ["ExceptionGroup: Error while running research and predictions: Errors: [\'RetryError: RetryError[<Future at 0x1f4ba1aa0b0 state=finished raised ValidationError>]\'] (1 sub-exception)"]', (ExceptionGroup("Error while running research and predictions: Errors: ['RetryError: RetryError[<Future at 0x1f4ba1aa0b0 state=finished raised ValidationError>]']", (RetryError(<Future at 0x1f4ba1aa0b0 state=finished raised ValidationError>),)),))]

---

## 2025-09-23 00:05:02,204
__main__ - ERROR
Error type: RuntimeError

---

## 2025-09-23 00:05:02,204
__main__ - ERROR
Full traceback: Traceback (most recent call last):
  File "C:\Users\jsgle\Desktop\AI\Guillotine Forecasting\guillotine-forecasting\main.py", line 1117, in <module>
    main()
    ~~~~^^
  File "C:\Users\jsgle\Desktop\AI\Guillotine Forecasting\guillotine-forecasting\main.py", line 1099, in main
    template_bot.log_report_summary(forecast_reports)
    ~~~~~~~~~~~~~~~~~~~~~~~~~~~~~~~^^^^^^^^^^^^^^^^^^
  File "C:\Users\jsgle\AppData\Roaming\pypoetry\venv\Lib\site-packages\forecasting_tools\forecast_bots\forecast_bot.py", line 806, in log_report_summary
    raise RuntimeError(
        f"{len(exceptions)} errors occurred while forecasting: {exceptions}"
    )
RuntimeError: 1 errors occurred while forecasting: [ExceptionGroup('Error while processing question url: \'dummy://test.com\': All 1 research reports/predictions failed: Errors: ["ExceptionGroup: Error while running research and predictions: Errors: [\'RetryError: RetryError[<Future at 0x1f4ba1aa0b0 state=finished raised ValidationError>]\'] (1 sub-exception)"]', (ExceptionGroup("Error while running research and predictions: Errors: ['RetryError: RetryError[<Future at 0x1f4ba1aa0b0 state=finished raised ValidationError>]']", (RetryError(<Future at 0x1f4ba1aa0b0 state=finished raised ValidationError>),)),))]


---

